<mujoco model="g1_lite_replay">
  <compiler angle="radian" autolimits="true" />
  <option timestep="0.0166667" gravity="0 0 -9.81" integrator="Euler" />

  <visual>
    <headlight ambient="0.6 0.6 0.6" diffuse="0.7 0.7 0.7" specular="0.1 0.1 0.1" />
    <rgba haze="0.15 0.25 0.35 1" />
  </visual>

  <asset>
    <material name="dark" rgba="0.18 0.18 0.2 1" />
    <material name="light" rgba="0.74 0.78 0.82 1" />
    <material name="accent" rgba="0.95 0.48 0.12 1" />
    <material name="limb" rgba="0.32 0.42 0.52 1" />
  </asset>

  <worldbody>
    <geom name="floor" type="plane" size="8 8 0.1" rgba="0.16 0.18 0.2 1" />

    <body name="pelvis_root" pos="0 0 0.79">
      <freejoint name="floating_base_joint" />
      <inertial pos="0 0 0" mass="12" diaginertia="0.25 0.25 0.25" />
      <geom name="pelvis_geom" type="box" size="0.13 0.085 0.055" material="dark" />

      <body name="left_hip_pitch_link" pos="0 0.064 -0.103">
        <joint name="left_hip_pitch_joint" axis="0 1 0" range="-2.6 2.9" />
        <geom type="sphere" size="0.045" material="light" />
        <body name="left_hip_roll_link">
          <joint name="left_hip_roll_joint" axis="1 0 0" range="-0.52 2.97" />
          <geom type="sphere" size="0.035" material="dark" />
          <body name="left_hip_yaw_link">
            <joint name="left_hip_yaw_joint" axis="0 0 1" range="-2.75 2.75" />
            <geom type="sphere" size="0.033" material="light" />
            <body name="left_knee_link" pos="0 0 -0.213">
              <joint name="left_knee_joint" axis="0 1 0" range="-0.09 2.62" />
              <geom type="capsule" fromto="0 0 0.17 0 0 -0.17" size="0.035" material="limb" />
              <body name="left_ankle_pitch_link" pos="0 0 -0.213">
                <joint name="left_ankle_pitch_joint" axis="0 1 0" range="-0.87 0.52" />
                <geom type="capsule" fromto="0 0 0.16 0 0 -0.04" size="0.03" material="light" />
                <body name="left_ankle_roll_link" pos="0 0 -0.05">
                  <joint name="left_ankle_roll_joint" axis="1 0 0" range="-0.26 0.26" />
                  <geom type="box" pos="0.035 0 -0.025" size="0.095 0.045 0.018" material="dark" />
                </body>
              </body>
            </body>
          </body>
        </body>
      </body>

      <body name="right_hip_pitch_link" pos="0 -0.064 -0.103">
        <joint name="right_hip_pitch_joint" axis="0 1 0" range="-2.6 2.9" />
        <geom type="sphere" size="0.045" material="light" />
        <body name="right_hip_roll_link">
          <joint name="right_hip_roll_joint" axis="1 0 0" range="-2.97 0.52" />
          <geom type="sphere" size="0.035" material="dark" />
          <body name="right_hip_yaw_link">
            <joint name="right_hip_yaw_joint" axis="0 0 1" range="-2.75 2.75" />
            <geom type="sphere" size="0.033" material="light" />
            <body name="right_knee_link" pos="0 0 -0.213">
              <joint name="right_knee_joint" axis="0 1 0" range="-0.09 2.62" />
              <geom type="capsule" fromto="0 0 0.17 0 0 -0.17" size="0.035" material="limb" />
              <body name="right_ankle_pitch_link" pos="0 0 -0.213">
                <joint name="right_ankle_pitch_joint" axis="0 1 0" range="-0.87 0.52" />
                <geom type="capsule" fromto="0 0 0.16 0 0 -0.04" size="0.03" material="light" />
                <body name="right_ankle_roll_link" pos="0 0 -0.05">
                  <joint name="right_ankle_roll_joint" axis="1 0 0" range="-0.26 0.26" />
                  <geom type="box" pos="0.035 0 -0.025" size="0.095 0.045 0.018" material="dark" />
                </body>
              </body>
            </body>
          </body>
        </body>
      </body>

      <body name="waist_yaw_link" pos="0 0 0.103">
        <joint name="waist_yaw_joint" axis="0 0 1" range="-2.62 2.62" />
        <geom type="cylinder" size="0.08 0.035" material="light" />
        <body name="waist_roll_link">
          <joint name="waist_roll_joint" axis="1 0 0" range="-0.52 0.52" />
          <geom type="sphere" size="0.055" material="dark" />
          <body name="waist_pitch_link" pos="0 0 0.04">
            <joint name="waist_pitch_joint" axis="0 1 0" range="-0.52 0.52" />
            <geom type="sphere" size="0.055" material="light" />
            <body name="torso_link" pos="0 0 0.14">
              <geom type="box" pos="0 0 0.08" size="0.12 0.095 0.18" material="dark" />
              <geom type="box" pos="0.012 0 0.1" size="0.123 0.098 0.022" material="accent" />
              <body name="head_link" pos="0 0 0.32">
                <geom type="sphere" size="0.07" material="light" />
              </body>

              <body name="left_shoulder_pitch_link" pos="0 0.161 0.204">
                <joint name="left_shoulder_pitch_joint" axis="0 1 0" range="-3.09 2.67" />
                <geom type="sphere" size="0.04" material="light" />
                <body name="left_shoulder_roll_link" pos="0 0.024 -0.103">
                  <joint name="left_shoulder_roll_joint" axis="1 0 0" range="-1.59 2.25" />
                  <geom type="sphere" size="0.034" material="dark" />
                  <body name="left_shoulder_yaw_link" pos="0 0.006 -0.103">
                    <joint name="left_shoulder_yaw_joint" axis="0 0 1" range="-2.62 2.62" />
                    <geom type="sphere" size="0.032" material="light" />
                    <body name="left_elbow_link" pos="0.19 0 -0.02">
                      <joint name="left_elbow_joint" axis="0 1 0" range="-1.05 2.09" />
                      <geom type="capsule" fromto="-0.17 0 0 0.02 0 0" size="0.028" material="limb" />
                      <body name="left_wrist_roll_link" pos="0.18 0 0">
                        <joint name="left_wrist_roll_joint" axis="1 0 0" range="-2.97 2.97" />
                        <geom type="capsule" fromto="-0.14 0 0 0.02 0 0" size="0.025" material="light" />
                        <body name="left_wrist_pitch_link" pos="0.04 0 0">
                          <joint name="left_wrist_pitch_joint" axis="0 1 0" range="-1.61 1.61" />
                          <geom type="sphere" size="0.024" material="dark" />
                          <body name="left_wrist_yaw_link" pos="0.046 0 0">
                            <joint name="left_wrist_yaw_joint" axis="0 0 1" range="-1.61 1.61" />
                            <geom type="box" pos="0.06 0.004 0" size="0.055 0.035 0.018" material="light" />
                          </body>
                        </body>
                      </body>
                    </body>
                  </body>
                </body>
              </body>

              <body name="right_shoulder_pitch_link" pos="0 -0.161 0.204">
                <joint name="right_shoulder_pitch_joint" axis="0 1 0" range="-3.09 2.67" />
                <geom type="sphere" size="0.04" material="light" />
                <body name="right_shoulder_roll_link" pos="0 -0.024 -0.103">
                  <joint name="right_shoulder_roll_joint" axis="1 0 0" range="-2.25 1.59" />
                  <geom type="sphere" size="0.034" material="dark" />
                  <body name="right_shoulder_yaw_link" pos="0 -0.006 -0.103">
                    <joint name="right_shoulder_yaw_joint" axis="0 0 1" range="-2.62 2.62" />
                    <geom type="sphere" size="0.032" material="light" />
                    <body name="right_elbow_link" pos="0.19 0 -0.02">
                      <joint name="right_elbow_joint" axis="0 1 0" range="-1.05 2.09" />
                      <geom type="capsule" fromto="-0.17 0 0 0.02 0 0" size="0.028" material="limb" />
                      <body name="right_wrist_roll_link" pos="0.18 0 0">
                        <joint name="right_wrist_roll_joint" axis="1 0 0" range="-2.97 2.97" />
                        <geom type="capsule" fromto="-0.14 0 0 0.02 0 0" size="0.025" material="light" />
                        <body name="right_wrist_pitch_link" pos="0.04 0 0">
                          <joint name="right_wrist_pitch_joint" axis="0 1 0" range="-1.61 1.61" />
                          <geom type="sphere" size="0.024" material="dark" />
                          <body name="right_wrist_yaw_link" pos="0.046 0 0">
                            <joint name="right_wrist_yaw_joint" axis="0 0 1" range="-1.61 1.61" />
                            <geom type="box" pos="0.06 -0.004 0" size="0.055 0.035 0.018" material="light" />
                          </body>
                        </body>
                      </body>
                    </body>
                  </body>
                </body>
              </body>
            </body>
          </body>
        </body>
      </body>
    </body>
  </worldbody>
</mujoco>
